Workbook
Name _rpe: Reference!$F$8:$R$16
Name benchlist: 'Personal Info'!$C:$C
Name query1: #REF!
Name bnmax: 'Personal Info'!$S$10
Name _meetsel: #REF!
Name bnmetrics: #REF!
Name _uom: 'Personal Info'!$L$5
Name dlmetrics: #REF!
Name sqmetrics: #REF!
Name squatlist: 'Personal Info'!$A:$A
Name progdt: 'Personal Info'!$L$25
Name gen: Training!$F$7
Name meetctdn: #REF!
Name dlmax: 'Personal Info'!$W$10
Name deadlist: 'Personal Info'!$E:$E
Name query2: #REF!
Name sqmax: 'Personal Info'!$O$10

Sheet Start Here
B2: WELCOME!
B3: PROGRAM EXPLANATION & FAQ
B6: BEGIN
B8: 1 | C8: Click FILE > MAKE A COPY at the top menu bar to create a copy of this program into your own Google Drive account. From there, you can edit the training file and make it your own.
B9: 2 | C9: Enter your current 1RMs on the Personal Info tab in the yellow boxes. You may also enter a low-rep, high-RPE set. Do not enter theoretical maxes or desired training outcomes. It is not needed to enter a 90% or 95% of your maxes...simply your maxes will do.
B10: 3 | C10: Look over the training plan, familiarize yourself with what is to come. We suggest running the plan without modification the first time through before attempting changes. Refer to our guide on RPE included for the best results.
B11: 4 | C11: =Hyperlink("mailto:support@thestrengthathlete.com","Read through the FAQ below, and if you have further questions, don't hesitate to email us by clicking here.") -> Read through the FAQ below, and if you have further questions, don't hesitate to email us by clicking here.
B12: 5 | C12: If you enjoyed the program, donate here and buy us a coffee!
C14: =HYPERLINK("http://www.thestrengthathlete.com/donate","DONATE HERE") -> DONATE HERE | G14: =HYPERLINK("mailto:support@thestrengthathlete.com","CONTACT US") -> CONTACT US
B20: THE PROGRAM
B22: This is a 9-week training approach designed for intermediate lifters to peak effectively into actual competitions (or a mock meet) with high performance. The first four weeks represent higher overall work and lower overall loading, designed to build training adaptions and muscle hypertrophy. We’ll deload on Week 5, shedding some fatigue and preparing for the next phase. Finally, we’ll peak with exposure to heavier loads, bringing out your best.
B24: While this is a generalized approach, meaning we aren’t targeting any individual athlete strengths or weaknesses or problem-solving strategies, it’s designed to overcome many of the shortcomings with powerlifting approaches we’ve seen. It additionally has an option for female and male athletes to make sure the approach is better tailored to your needs. This is the intermediate approach we wish all athletes had access to, with balanced volume, intensity, and frequency.
B26: As our training methods continue to evolve, we’ve updated the intermediate approach to match those changes. You’ll see an increased use of autoregulation and the addition of lower repetition top sets with higher repetition backoff work to combine the best of both worlds. As you get close to peaking, you’ll see some subtle changes to the peaking structure to ride the line between fitness and fatigue. We think you’ll really like it.
B28: For squat, we begin with higher training volume over two days per week of training frequency. We already have some exposure to higher intensities early on, allowing the athlete large amounts of time for low-repetition adaptations to occur. We’ll build overall lower body strength with the overall amount of volume (and added leg pressing work), and increased skill with high specificity. We utilize multiple rep ranges to ensure maximum strength and hypertrophy.
B30: For bench press, we include regular exposure to pressing to allow for accelerated rates of progress. Athletes will handle horizontal pressing four times a week with access to singles starting on week 1. More than likely, you’re about to bench more than you have in a long time.
B32: For deadlift, we have a fantastic balance of competition work with paused work, designed to teach technique and bracing and ultimately improve positioning. There’s a delayed shift for heavy work on deadlift until much later in the training approach to allow space for building strength before we test strength.
B34: WHO & WHY
B36: Q: | C36: Who is this program designed for?
B37: A: | C37: We’ve defined a sample athlete for this program as a male or female with some experience in resistance training, and around two years of experience in powerlifting. If you have less than six months' experience, we suggest the TSA Beginner Approach. If you have one to two years' experience, we suggest the TSA Intermediate 1.0 Aopproach. This sample athlete is healthy, has no current injuries or movement limitations, and can effectively train four times per week. Ideally, this athlete is eating in a small to moderate caloric surplus, sleeping 7-10 hours per night, and stressing as little (or as predictably) as possible.
B39: Q: | C39: What if this program is too hard?
B40: A: | C40: This program is purposefully designed for intermediate lifters who want to prepare for 1RM tests in 9 weeks. If you think you’re a more beginner lifter, check out our free TSA Beginner Approach, or consider working one on one with a TSA coach to make sure training is continually tailored to you and your goals. You can also modify this program with less frequency, less training volume, or lower average loads.
B42: Q: | C42: What do I need to do before this program?
B43: A: | C43: You need to have done a heavy set of 1-3 reps at RPE 8.5-10 on squat, bench press, and deadlift in the last 3 months. This is so you can populate the loads you'll be using on the plan.
B45: Q: | C45: What are the requirements to run this program?
B46: A: | C46: Have access to any equipment necessary to effectively train, understand RPE and how to rate RPE. Have four available training days in your work/school/life schedule.
B48: ABOUT THE PROGRAM
B50: Q: | C50: Why the top sets on squats and bench press so early?
B51: A: | C51: The little bit of added heavier work early on gives the athletes some intensity ideas for the RPE-based work in the second half of the training cycle. Additionally, they increase skill acquisition and neural efficiency early on, which should translate to better performance in competition.
B53: Q: | C53: Why the "Athlete Movement of Choice"?
B54: A: | C54: Some research and our own observation suggests athletes feel a lack of control over a training approach that was entirely written without their input. Giving the athlete freedom to select some parts of the training approach gives them a sense of ownership and control, further increasing buy-in and adherence as a result. It's a chance for you to contribute and engage with the approach
B56: Q: | C56: What is the difference from selecting ‘male’ to selecting ‘female’?
B57: A: | C57: We have added slightly more training volume for female athletes, as they likely require it to make the same level of progress. The additions in training volume exist across bench press exclusively.
B59: Q: | C59: What is lsRPE? What’s RPE?
B60: A: | C60: lsRPE stands for ‘last set RPE’, the RPE of your very final set of a specific exercise. For information on RPE, please check the tab ‘RPE’.
B62: ADJUSTMENTS
B64: Q: | C64: What if I miss reps?
B65: A: | C65: We’ve planned approaches such that most athletes shouldn’t miss reps if you check your recovery boxes (sleep, adequate calories, adequate protein intake) and use appropriate 1 rep maxes. If you happen to miss reps for any reason, don’t panic. Simply move forward with the program as if it never happened. If it becomes a recurring issue, you may need to adjust loads. This is normal and part of the individualization of the training process.
B67: Q: | C67: What if I overshoot my RPE?
B68: A: | C68: Again, don’t panic. As you learn to use RPE, you will overshoot RPE sometimes and undershoot other times. Just make a mental note and aim to be more accurate in the future. If it’s a regular problem, you may ask yourself why you feel the need to overshoot RPE. Do you not trust the training approach? Are you having a hard time gauging effort? Are you just ego lifting? Getting to the root of this issue will make you a better lifter overall.
B70: Q: | C70: What if I can't do the required number of pullups?
...

Sheet Personal Info
A3: List of Squat | C3: List of Bench | E3: List of Deadlift
A4: SQ | B4: {=IF(A4:A108="",,"sq")} -> sq | C4: bn | D4: {=IF(C4:C108="",,"bn")} -> bn | E4: dl | F4: {=IF(E4:E108="",,"dl")} -> dl
A5: sq | B5: sq | C5: BN | D5: bn | E5: DL | F5: dl | K5: UNIT OF MEASURE | L5: lbs
A6: Leg Press | B6: sq | C6: Bananas | D6: bn | E6: Deadlift | F6: dl
A7: Squat | B7: sq | C7: Bench Press | D7: bn | E7: Sumo Deadlift | F7: dl | K7: CURRENT
A8: Front Squat | B8: sq | C8: 3:1:0 Tempo Bench | D8: bn | E8: Deadlift | F8: dl
A9: squat | B9: sq | C9: Bench | D9: bn | E9: Comp Deadlit | F9: dl | K9: DATE | L9: WEIGHT | M9: X REPS | O9: SQUAT | P9: WEIGHT | Q9: X REPS | S9: BENCH | T9: WEIGHT | U9: X REPS | W9: DEADLIFT
A10: Comp Squat | B10: sq | C10: Bench | D10: bn | E10: Competition Deadlift | F10: dl | K10: =IFERROR(__xludf.DUMMYFUNCTION("FILTER(K15:W21,K15:K21=MAX(K15:K21))"),46109.0) -> 46109 | L10: =IFERROR(__xludf.DUMMYFUNCTION("""COMPUTED_VALUE"""),200.0) -> 200 | M10: =IFERROR(__xludf.DUMMYFUNCTION("""COMPUTED_VALUE"""),1.0) -> 1 | N10: =IFERROR(__xludf.DUMMYFUNCTION("""COMPUTED_VALUE"""),10.0) -> 10 | O10: =IFERROR(__xludf.DUMMYFUNCTION("""COMPUTED_VALUE"""),200.0) -> 200 | P10: =IFERROR(__xludf.DUMMYFUNCTION("""COMPUTED_VALUE"""),120.0) -> 120 | Q10: =IFERROR(__xludf.DUMMYFUNCTION("""COMPUTED_VALUE"""),1.0) -> 1 | R10: =IFERROR(__xludf.DUMMYFUNCTION("""COMPUTED_VALUE"""),10.0) -> 10 | S10: =IFERROR(__xludf.DUMMYFUNCTION("""COMPUTED_VALUE"""),120.0) -> 120 | T10: =IFERROR(__xludf.DUMMYFUNCTION("""COMPUTED_VALUE"""),220.0) -> 220 | U10: =IFERROR(__xludf.DUMMYFUNCTION("""COMPUTED_VALUE"""),1.0) -> 1 | V10: =IFERROR(__xludf.DUMMYFUNCTION("""COMPUTED_VALUE"""),9.5) -> 9.5 | W10: =IFERROR(__xludf.DUMMYFUNCTION("""COMPUTED_VALUE"""),224.94887525562373) -> 224.94888
A11: Squat | B11: sq | C11: Bench Press | D11: bn | E11: Comp Stance Deadlift | F11: dl
A12: Barbell Squat | B12: sq | C12: Paused Bench | D12: bn | E12: Competition Stance Deadlift | F12: dl | K12: PREVIOUS
A13: Paused Squat | B13: sq | C13: Pause Bench | D13: bn | E13: Conv Deadlift | F13: dl
A14: Paused Squat, 2ct | B14: sq | C14: Pause Bench Press | D14: bn | E14: Conventional Deadlift | F14: dl | K14: DATE | L14: WEIGHT | M14: X REPS | N14: RPE | O14: SQUAT | P14: WEIGHT | Q14: X REPS | R14: RPE | S14: BENCH | T14: WEIGHT | U14: X REPS | V14: RPE | W14: DEADLIFT
A15: Paused Squat, 2 count | B15: sq | C15: Paused Bench Press | D15: bn | E15: Sumo Deadlift | F15: dl | J15: 1 | K15: =TODAY() -> 46109 | L15: 200 | M15: 1 | N15: 10 | O15: {=IF(ISBLANK(L15:L21),"",L15:L21/IF(ISBLANK(N15:N21),(1.0278-(0.0278*M15:M21)),IFERROR(VLOOKUP(N15:N21*1,_rpe,M15:M21+1,0),1)))} -> 200 | P15: 120 | Q15: 1 | R15: 10 | S15: {=IF(ISBLANK(P15:P21),"",P15:P21/IF(ISBLANK(R15:R21),(1.0278-(0.0278*Q15:Q21)),IFERROR(VLOOKUP(R15:R21*1,_rpe,Q15:Q21+1,0),1)))} -> 120 | T15: 220 | U15: 1 | V15: 9.5 | W15: {=IF(ISBLANK(T15:T21),"",T15:T21/IF(ISBLANK(V15:V21),(1.0278-(0.0278*U15:U21)),IFERROR(VLOOKUP(V15:V21*1,_rpe,U15:U21+1,0),1)))} -> 224.94888
A16: Squat w/ Belt | B16: sq | C16: Paused Bench, 2ct | D16: bn | E16: Sumo DL | F16: dl | J16: 2
A17: Beltless Squat | B17: sq | C17: Paused Bench, 2 count | D17: bn | E17: Conv DL | F17: dl | J17: 3
A18: Squat Walkout | B18: sq | C18: Pause Bench, 2ct | D18: bn | E18: Conventional DL | F18: dl | J18: 4
A19: Front Squat | B19: sq | C19: Paused Bench, 2 count | D19: bn | E19: Block Pull | F19: dl | J19: 5
A20: SSB Squat | B20: sq | C20: Spoto Press | D20: bn | E20: Rack Pull | F20: dl | J20: 6
A21: Safety Bar Squat | B21: sq | C21: Larsen Press | D21: bn | E21: Snatch Grip Deadlift | F21: dl | J21: 7
A22: Squat w/Bands | B22: sq | C22: 2-board Press | D22: bn | E22: Deficit DL | F22: dl
A23: Squat with Bands | B23: sq | C23: Close Grip Bench Press | D23: bn | E23: Deficit Deadlift | F23: dl | K23: NUTRITION/BASICS | P23: MACROS
A24: Squat w/Chains | B24: sq | C24: CGBP | D24: bn | E24: Deficit Deadlift, 2" | F24: dl
A25: Squat with Chains | B25: sq | C25: 1-board Press | D25: bn | E25: Deficit Deadlift, 4" | F25: dl | K25: START OF TRAINING | L25: =TODAY() -> 46109 | P25: DAY | Q25: FAT | R25: CARBS | S25: PROTEIN | T25: CALORIES
A26: Box Squat | B26: sq | C26: Bench Press w/board | D26: bn | E26: Deficit Deadlift, 6" | F26: dl | K26: FIRST NAME | L26: First | P26: HIGH CALORIE DAYS | Q26: =Q27-Q28&"-"&Q27+Q28&"g" -> -5-5g | R26: =R27-R28&"-"&R27+R28&"g" -> #NUM! | S26: =S27-S28&"-"&S27+S28&"g" -> 170-190g | T26: =((R27-R28)*4+(S27-S28)*4+(Q27-Q28)*9&" - "&((R27+R28)*4+(S27+S28)*4+(Q27+Q28)*9)&" kcals") -> #NUM!
A27: Smith Machine Squat | B27: sq | C27: Incline Bench | D27: bn | E27: Deadlift to Knees | F27: dl | K27: LAST NAME | L27: Last | P27: EXACT | Q27: ='Personal Info'!L50 -> 0 | R27: ='Personal Info'!L51 -> #NUM! | S27: ='Personal Info'!L52 -> 180 | T27: =R27*4+S27*4+Q27*9 -> #NUM!
A28: Front Box Squat | B28: sq | C28: Decline Bench | D28: bn | E28: Deadlift to Knees + Finish | F28: dl | K28: HEIGHT | L28: 5'6" | P28: WINDOW | Q28: 5 | R28: 10 | S28: 10
A29: Double Paused Squat | B29: sq | C29: DB Bench | D29: bn | E29: Deadlift w/ 2 Pauses | F29: dl | K29: AGE | L29: 18 | P29: LOW CALORIE DAYS | Q29: =IF(Q30-Q31<0, 0, Q30-Q31&"-"&Q30+Q31&"g") -> 0 | R29: =IF(R30-R31<0,0,R30-R31&"-"&R30+R31&"g") -> 0 | S29: =IF(S30-S31<0,0,S30-S31&"-"&S30+S31&"g") -> 0 | T29: =IF((R30-R31)*4+(S30-S31)*4+(Q30-Q31)*9<0,0,((R30-R31)*4+(S30-S31)*4+(Q30-Q31)*9&" - "&((R30+R31)*4+(S30+S31)*4+(Q30+Q31)*9)&" kcals")) -> 0
A30: Dbl Paused Squat | B30: sq | C30: Incline DB Bench | D30: bn | E30: Deadlift w/chains | F30: dl | K30: STARTING BW | L30: 180 | P30: EXACT | Q30: ='Personal Info'!L55 -> 0 | R30: ='Personal Info'!L56 -> 0 | S30: ='Personal Info'!L57 -> 0 | T30: =R30*4+S30*4+Q30*9 -> 0
A31: Slow Squat | B31: sq | C31: Decline DB Bench | D31: bn | E31: Deadlift w/ Chains | F31: dl | K31: MAINTENANCE KCALS | L31: =IFERROR(IF(_uom="lbs",L30,L30*2.20462)*10*L33, "enter here or activity level") -> 2700 | P31: WINDOW | Q31: 5 | R31: 10 | S31: 10
A32: Competition Squat | B32: sq | C32: Push Up | D32: bn | E32: Deadlift with chains | F32: dl | K32: ACTIVITY LEVEL | L32: Lightly active plus 3-6 days of weight lifting
A33: High Bar Squat | B33: sq | C33: Pushup | D33: bn | E33: Deadlift w/bands | F33: dl | K33: ="RANGE: "&IF(L32=Home!T44,"1.3 - 1.6", IF(L32=Home!T45, "1.5 - 1.8", IF(L32=Home!T46, "1.7 - 2.0", IF(L32=Home!T47,"1.9 - 2.2","n/a")))) -> RANGE: 1.5 - 1.8 | L33: 1.5
A34: Low Bar Squat | B34: sq | C34: Weighted pushup | D34: bn | E34: Deadlift with bands | F34: dl | K34: SEX | L34: SELECT
A35: Zercher Squat | B35: sq | C35: Weighted Push Up | D35: bn | E35: Romanian Deadlift | F35: dl | K35: BF% | L35: Select here
A36: Pin Squat | B36: sq | C36: Floor Press | D36: bn | E36: RDL | F36: dl | K36: LEAN GAIN OR CUT? | L36: select here | P36: CARDIO
A37: Squat to Pins | B37: sq | C37: DB Floor Press | D37: bn | E37: SLDL | F37: dl | K37: =IF(L36="Lean gain","NOVICE, INT, OR ADVANCED?", IF(L36="Cutting phase", "RATE OF WEIGHT LOSS","CHOOSE LEAN GAIN OR CUT ABOVE")) -> CHOOSE LEAN GAIN OR CUT ABOVE | L37: Select here
A38: Paused High Bar Squat | B38: sq | C38: Bench over Foam | D38: bn | E38: Stiff Legged Deadlift | F38: dl | Q38: SESSIONS/WK | R38: KCAL/SESSION | S38: TOTAL KCAL/WK | T38: eKCALS/10 MINS
A39: Paused Front Squat | B39: sq | C39: Slow Bench | D39: bn | E39: Sumo Block Pull | F39: dl | K39: =IF(L36="Cutting phase", "# REFEEDS: (RECOMMEND "&IF(L36="Select here", "",IF(L36="Lean gain","", IF(OR(AND(L34="Male",L35>=0.2),AND(L34="Female",L35>=0.28)), 1, IF(OR(AND(L34="Male",L35>=0.12,L35<=0.19),AND(L34="Female",L35>=0.2,L35<=0.27)), 2, IF(OR(AND(L34="Male",L35<0.12),AND(L34="Female",L35<0.2)), 3, "")))))&")", "HIGH DAYS?") -> HIGH DAYS? | P39: LISS | S39: =Q39*R39 -> 0 | T39: {=MROUND(INDEX(Home!E22:E108,COUNTA(Home!E22:E108),1)*0.2,5)&"-"&MROUND(INDEX(Home!E22:E108,COUNTA(Home!E22:E108),1)*0.45,5)} -> 0-0
A40: Tempo Squat (3:1:3) | B40: sq | C40: Reverse Grip Bench | D40: bn | E40: 1 + 1/2 Deadlift | F40: dl | K40: =IF(L36="Lean gain", "DAILY KCALS:", IF(L36="Cutting phase","LOW DAY KCALS:", "")) | L40: =IFERROR(IF(L36="Select here","", IF(L36="Lean gain", L31+IF(L37=Home!T32,(IF(_uom="lbs",L30,L30*2.20462)*0.015*3500)/4/7,IF(L37=Home!T33,(IF(_uom="lbs",L30,L30*2.20462)*0.01*3500)/4/7,IF(L37=Home!T34,(IF(_uom="lbs",L30,L30*2.20462)*0.005*3500)/4/7))), L31 - (3500 * IF(_uom="lbs",L30,L30*2.20462)*IF(L37=Home!T38, 0.01, IF(L37=Home!T39, 0.0075, IF(L37=Home!T40, 0.005, "bananas")))) / (7-L39))), "") | P40: HIIT | R40: #intervals: | T40: {=MROUND(INDEX(Home!E22:E108,COUNTA(Home!E22:E108),1)*0.45,5)&"-"&MROUND(INDEX(Home!E22:E108,COUNTA(Home!E22:E108),1)*0.7,5)} -> 0-0
A41: Tempo Squat (3:0:3) | B41: sq | C41: Bench Lockout | D41: bn | E41: Paused DL | F41: dl | K41: =IF(L36="Cutting phase", "REFEED KCALS:", IF(AND(K39="HIGH DAYS?",OR(L39="",0)),"","HIGH DAYS:")) | L41: =IF(L39=0,"",L31)
A42: Goblet Squat | B42: sq | C42: Pin Bench | D42: bn | E42: Paused Deadlift | F42: dl
...

Sheet Training
E2: INTRO/ACCLIMATION | S2: PROGRESS 1 | AG2: PROGRESS 2 | AU2: PROGRESS 3 | BI2: DELOAD/INTENSITY PREP | BW2: INTENSIFY/PEAK 1 | CK2: INTENSIFY/PEAK 2 | CY2: INTENSIFY/PEAK 3 | DM2: TEST/COMPETE
E3: 1 | S3: =E3+1 -> 2 | AG3: =S3+1 -> 3 | AU3: =AG3+1 -> 4 | BI3: =AU3+1 -> 5 | BW3: =BI3+1 -> 6 | CK3: =BW3+1 -> 7 | CY3: =CK3+1 -> 8 | DM3: =CY3+1 -> 9
C4: =Yearly!$G$9 -> #REF! | D4: =Yearly!$G$9+6 -> #REF! | E4: 9 WEEKS OUT, PEAK LIFT INTENSITY 5-7.5 RPE | Q4: =D4+1 -> #REF! | R4: =Q4+6 -> #REF! | S4: 8 WEEKS OUT, PEAK LIFT INTENSITY 6-8RPE | AE4: =R4+1 -> #REF! | AF4: =AE4+6 -> #REF! | AG4: 7 WEEKS OUT, PEAK LIFT INTENSITY 6-8 RPE | AS4: =AF4+1 -> #REF! | AT4: =AS4+6 -> #REF! | AU4: 6 WEEKS OUT, PEAK LIFT INTENSITY 7-8.5 RPE | BG4: =AT4+1 -> #REF! | BH4: =BG4+6 -> #REF! | BI4: 5 WEEKS OUT, PEAK LIFT INTENSITY 5-7 RPE | BU4: =BH4+1 -> #REF! | BV4: =BU4+6 -> #REF! | BW4: 4 WEEKS OUT, PEAK LIFT INTENSITY 7-8.5 RPE | CI4: =BV4+1 -> #REF! | CJ4: =CI4+6 -> #REF! | CK4: 3 WEEKS OUT, PEAK LIFT INTENSITY 8-9 RPE | CW4: =CJ4+1 -> #REF! | CX4: =CW4+6 -> #REF! | CY4: 2 WEEKS OUT, PEAK LIFT INTENSITY 8-9 RPE | DK4: =CX4+1 -> #REF! | DL4: =DK4+6 -> #REF! | DM4: TEST WEEK | IX4: =#REF!+1 -> #REF! | IY4: =IX4+6 -> #REF!
U6: 1 | V6: 1 | W6: 1 | AI6: =U$6 -> 1 | AJ6: =V$6 -> 1 | AK6: =W$6 -> 1 | AW6: =AI$6 -> 1 | AX6: =AJ$6 -> 1 | AY6: =AK$6 -> 1 | BK6: =AW$6 -> 1 | BL6: =AX$6 -> 1 | BM6: =AY$6 -> 1 | BY6: =BK$6 -> 1 | BZ6: =BL$6 -> 1 | CA6: =BM$6 -> 1 | CM6: =BY$6 -> 1 | CN6: =BZ$6 -> 1 | CO6: =CA$6 -> 1 | DA6: =CM$6 -> 1 | DB6: =CN$6 -> 1 | DC6: =CO$6 -> 1 | DO6: =DA$6 -> 1 | DP6: =DB$6 -> 1 | DQ6: =DC$6 -> 1
E7: are you male or female? | F7: SELECT | U7: =VLOOKUP(U$6,'Personal Info'!$J$15:$W$21,6) -> 200 | V7: =VLOOKUP(V$6,'Personal Info'!$J$15:$W$21,10) -> 120 | W7: =VLOOKUP(W$6,'Personal Info'!$J$15:$W$21,14) -> 224.94888 | AI7: =VLOOKUP(AI$6,'Personal Info'!$J$15:$W$21,6) -> 200 | AJ7: =VLOOKUP(AJ$6,'Personal Info'!$J$15:$W$21,10) -> 120 | AK7: =VLOOKUP(AK$6,'Personal Info'!$J$15:$W$21,14) -> 224.94888 | AW7: =VLOOKUP(AW$6,'Personal Info'!$J$15:$W$21,6) -> 200 | AX7: =VLOOKUP(AX$6,'Personal Info'!$J$15:$W$21,10) -> 120 | AY7: =VLOOKUP(AY$6,'Personal Info'!$J$15:$W$21,14) -> 224.94888 | BK7: =VLOOKUP(BK$6,'Personal Info'!$J$15:$W$21,6) -> 200 | BL7: =VLOOKUP(BL$6,'Personal Info'!$J$15:$W$21,10) -> 120 | BM7: =VLOOKUP(BM$6,'Personal Info'!$J$15:$W$21,14) -> 224.94888 | BY7: =VLOOKUP(BY$6,'Personal Info'!$J$15:$W$21,6) -> 200 | BZ7: =VLOOKUP(BZ$6,'Personal Info'!$J$15:$W$21,10) -> 120 | CA7: =VLOOKUP(CA$6,'Personal Info'!$J$15:$W$21,14) -> 224.94888 | CM7: =VLOOKUP(CM$6,'Personal Info'!$J$15:$W$21,6) -> 200 | CN7: =VLOOKUP(CN$6,'Personal Info'!$J$15:$W$21,10) -> 120 | CO7: =VLOOKUP(CO$6,'Personal Info'!$J$15:$W$21,14) -> 224.94888 | DA7: =VLOOKUP(DA$6,'Personal Info'!$J$15:$W$21,6) -> 200 | DB7: =VLOOKUP(DB$6,'Personal Info'!$J$15:$W$21,10) -> 120 | DC7: =VLOOKUP(DC$6,'Personal Info'!$J$15:$W$21,14) -> 224.94888 | DP7: =VLOOKUP(DP$6,'Personal Info'!$J$15:$W$21,10) -> 120 | DQ7: =VLOOKUP(DQ$6,'Personal Info'!$J$15:$W$21,14) -> 224.94888
C9: label | D9: date | E9: Day 1 | F9: sets | G9: reps | H9: intensity | I9: load | J9: e1RM | L9: lsRPE | M9: e1RM | N9: notes | Q9: label | R9: date | S9: Day 1 | T9: sets | U9: reps | V9: intensity | W9: load | X9: e1RM | Z9: lsRPE | AA9: e1RM | AB9: notes | AE9: label | AF9: date | AG9: Day 1 | AH9: sets | AI9: reps | AJ9: intensity | AK9: load | AL9: e1RM | AN9: lsRPE | AO9: e1RM | AP9: notes | AS9: label | AT9: date | AU9: Day 1 | AV9: sets | AW9: reps | AX9: intensity | AY9: load | AZ9: e1RM | BB9: lsRPE | BC9: e1RM | BD9: notes | BG9: label | BH9: date | BI9: Day 1 | BJ9: sets | BK9: reps | BL9: intensity | BM9: load | BN9: e1RM | BP9: lsRPE | BQ9: e1RM | BR9: notes | BU9: label | BV9: date | BW9: Day 1 | BX9: sets | BY9: reps | BZ9: intensity | CA9: load | CB9: e1RM | CD9: lsRPE | CE9: e1RM | CF9: notes | CI9: label | CJ9: date | CK9: Day 1 | CL9: sets | CM9: reps | CN9: intensity | CO9: load | CP9: e1RM | CR9: lsRPE | CS9: e1RM | CT9: notes | CW9: label | CX9: date | CY9: Day 1 | CZ9: sets | DA9: reps | DB9: intensity | DC9: load | DD9: e1RM | DF9: lsRPE | DG9: e1RM | DH9: notes | DK9: label | DL9: date | DM9: Day 1 | DN9: sets | DO9: reps | DP9: intensity | DQ9: load | DR9: e1RM | DT9: lsRPE | DU9: e1RM | DV9: notes | IX9: label | IY9: date
B10: SQ 1: hypertrophy | C10: =IFERROR(__xludf.DUMMYFUNCTION("ARRAYFORMULA(IF(ISBLANK(E10:E210),"""", IF(ISNA(LOOKUP(ROW(E10:E210),FILTER(ROW(E10:E210),LEN(E10:E210)>1),VLOOKUP(FILTER(E10:E210,LEN(E10:E210)>1),{'Personal Info'!$A:$B;'Personal Info'!$C:$D;'Personal Info'!$E:$F},2,FALSE))), ""ac"" , LOOKUP(ROW(E10:E21"&"0),FILTER(ROW(E10:E210),LEN(E10:E210)>1),VLOOKUP(FILTER(E10:E210,LEN(E10:E210)>1),{'Personal Info'!$A:$B;'Personal Info'!$C:$D;'Personal Info'!$E:$F},2,FALSE)))))"),"sq") -> sq | D10: {=IF(WEEKDAY(progdt)=1, progdt+1, progdt +2-MOD(WEEKDAY(progdt),7))*ROW(INDIRECT("A1:A190"))^0} -> 46111 | E10: Competition Squat | F10: 1 | G10: 3 | H10: 80 | I10: {=IFERROR(IF(C10="ac"+ISNUMBER(SEARCH("'",H10))+G10="","", MROUND(SWITCH(C10,"sq",'Personal Info'!$O$15,"bn",'Personal Info'!$S$15,"dl",'Personal Info'!$W$15,"")*IF(H10>10, H10/100, VLOOKUP(H10, _rpe,SUBSTITUTE(G10,"+","")+1,0)), IF( SWITCH(C10:C210,"sq",'Personal Info'!$O$15,"bn",'Personal Info'!$S$15,"dl", 'Personal Info'!$W$15,"")< IF(_uom="lbs", 175, 80), 1.25, IF(_uom="lbs",5,2.5)))),"")} -> 160 | J10: {=IF(C10:C210="",,IFERROR(I10:I210/VLOOKUP(L10:L210, _rpe,SUBSTITUTE(G10:G210,"+","")+1,FALSE)*1,""))} | M10: =IFERROR(__xludf.DUMMYFUNCTION("IF(I10=MAX(FILTER(I$10:I$199,LOOKUP(ROW(C$10:C$199),FILTER(ROW(C$10:C$199),C$10:C$199<>C$9:C$198))=LOOKUP(ROW(C10),FILTER(ROW(C$10:C$199),C$10:C$199<>C$9:C$198)))),J10,)"),"") | P10: =IF(ISBLANK(B10),"",B10) -> SQ 1: hypertrophy | Q10: =IFERROR(__xludf.DUMMYFUNCTION("ARRAYFORMULA(IF(S10:S210="""","""", IF(ISNA(LOOKUP(ROW(S10:S210),FILTER(ROW(S10:S210),LEN(S10:S210)>1),VLOOKUP(FILTER(S10:S210,LEN(S10:S210)>1),{'Personal Info'!$A:$B;'Personal Info'!$C:$D;'Personal Info'!$E:$F},2,FALSE))), ""ac"" , LOOKUP(ROW(S10:S210),F"&"ILTER(ROW(S10:S210),LEN(S10:S210)>1),VLOOKUP(FILTER(S10:S210,LEN(S10:S210)>1),{'Personal Info'!$A:$B;'Personal Info'!$C:$D;'Personal Info'!$E:$F},2,FALSE)))))"),"sq") -> sq | R10: {=(D10+7)*ROW(INDIRECT("A1:A190"))^0} -> 46118 | S10: =IF(ISBLANK(E10),"",E10) -> Competition Squat | T10: 1 | U10: =IF( OR(ISBLANK(G10),G10=""),"", G10) -> 3 | V10: 82 | W10: {=IFERROR(IF(Q10="ac"+ISNUMBER(SEARCH("'",V10))+U10="","", IF(ISNUMBER(SEARCH("lw",V10)), I10 + SUBSTITUTE(V10,"lw+",""), MROUND(SWITCH(Q10,"sq",U$7,"bn",V$7,"dl",W$7,"")*IF(V10>10, V10/100, VLOOKUP(V10, _rpe,SUBSTITUTE(U10,"+","")+1,0)), IF( SWITCH(Q10,"sq",U$7,"bn",V$7,"dl", W$7,"")< IF(_uom="lbs", 175, 80), 1.25, IF(_uom="lbs",5,2.5))))), "")} -> 165 | X10: {=IF(Q10:Q210="",,IFERROR(W10:W210/VLOOKUP(Z10:Z210, _rpe,SUBSTITUTE(U10:U210,"+","")+1,FALSE)*1,""))} | AA10: =IFERROR(__xludf.DUMMYFUNCTION("IF(W10=MAX(FILTER(W$10:W$199,LOOKUP(ROW(Q$10:Q$199),FILTER(ROW(Q$10:Q$199),Q$10:Q$199<>Q$9:Q$198))=LOOKUP(ROW(Q10),FILTER(ROW(Q$10:Q$199),Q$10:Q$199<>Q$9:Q$198)))),X10,)"),"") | AD10: =IF(ISBLANK(P10),"",P10) -> SQ 1: hypertrophy | AE10: =IFERROR(__xludf.DUMMYFUNCTION("ARRAYFORMULA(IF(AG10:AG210="""","""", IF(ISNA(LOOKUP(ROW(AG10:AG210),FILTER(ROW(AG10:AG210),LEN(AG10:AG210)>1),VLOOKUP(FILTER(AG10:AG210,LEN(AG10:AG210)>1),{'Personal Info'!$A:$B;'Personal Info'!$C:$D;'Personal Info'!$E:$F},2,FALSE))), ""ac"" , LOOKUP(ROW"&"(AG10:AG210),FILTER(ROW(AG10:AG210),LEN(AG10:AG210)>1),VLOOKUP(FILTER(AG10:AG210,LEN(AG10:AG210)>1),{'Personal Info'!$A:$B;'Personal Info'!$C:$D;'Personal Info'!$E:$F},2,FALSE)))))"),"sq") -> sq | AF10: {=(R10+7)*ROW(INDIRECT("A1:A190"))^0} -> 46125 | AG10: =IF(ISBLANK(S10),"",S10) -> Competition Squat | AH10: =IF(ISBLANK(T10),"",T10) -> 1 | AI10: =IF( OR(ISBLANK(U10),U10=""),"", U10) -> 3 | AJ10: 84 | AK10: {=IFERROR(IF(AE10="ac"+ISNUMBER(SEARCH("'",AJ10))+AI10="","", IF(ISNUMBER(SEARCH("lw",AJ10)), W10 + SUBSTITUTE(AJ10,"lw+",""), MROUND(SWITCH(AE10,"sq",AI$7,"bn",AJ$7,"dl",AK$7,"")*IF(AJ10>10, AJ10/100, VLOOKUP(AJ10, _rpe,SUBSTITUTE(AI10,"+","")+1,0)), IF( SWITCH(AE10,"sq",AI$7,"bn",AJ$7,"dl", AK$7,"")< IF(_uom="lbs", 175, 80), 1.25, IF(_uom="lbs",5,2.5))))), "")} -> 170 | AL10: {=IF(AE10:AE210="",,IFERROR(AK10:AK210/VLOOKUP(AN10:AN210, _rpe,SUBSTITUTE(AI10:AI210,"+","")+1,FALSE)*1,""))} | AO10: =IFERROR(__xludf.DUMMYFUNCTION("IF(AK10=MAX(FILTER(AK$10:AK$199,LOOKUP(ROW(AE$10:AE$199),FILTER(ROW(AE$10:AE$199),AE$10:AE$199<>AE$9:AE$198))=LOOKUP(ROW(AE10),FILTER(ROW(AE$10:AE$199),AE$10:AE$199<>AE$9:AE$198)))),AL10,)"),"") | AR10: =IF(ISBLANK(AD10),"",AD10) -> SQ 1: hypertrophy | AS10: =IFERROR(__xludf.DUMMYFUNCTION("ARRAYFORMULA(IF(AU10:AU210="""","""", IF(ISNA(LOOKUP(ROW(AU10:AU210),FILTER(ROW(AU10:AU210),LEN(AU10:AU210)>1),VLOOKUP(FILTER(AU10:AU210,LEN(AU10:AU210)>1),{'Personal Info'!$A:$B;'Personal Info'!$C:$D;'Personal Info'!$E:$F},2,FALSE))), ""ac"" , LOOKUP(ROW"&"(AU10:AU210),FILTER(ROW(AU10:AU210),LEN(AU10:AU210)>1),VLOOKUP(FILTER(AU10:AU210,LEN(AU10:AU210)>1),{'Personal Info'!$A:$B;'Personal Info'!$C:$D;'Personal Info'!$E:$F},2,FALSE)))))"),"sq") -> sq | AT10: {=(AF10+7)*ROW(INDIRECT("A1:A190"))^0} -> 46132 | AU10: =IF(ISBLANK(AG10),"",AG10) -> Competition Squat | AV10: =IF(ISBLANK(AH10),"",AH10) -> 1 | AW10: =IF( OR(ISBLANK(AI10),AI10=""),"", AI10) -> 3 | AX10: 86 | AY10: {=IFERROR(IF(AS10="ac"+ISNUMBER(SEARCH("'",AX10))+AW10="","", IF(ISNUMBER(SEARCH("lw",AX10)), AK10 + SUBSTITUTE(AX10,"lw+",""), MROUND(SWITCH(AS10,"sq",AW$7,"bn",AX$7,"dl",AY$7,"")*IF(AX10>10, AX10/100, VLOOKUP(AX10, _rpe,SUBSTITUTE(AW10,"+","")+1,0)), IF( SWITCH(AS10,"sq",AW$7,"bn",AX$7,"dl", AY$7,"")< IF(_uom="lbs", 175, 80), 1.25, IF(_uom="lbs",5,2.5))))), "")} -> 170 | AZ10: {=IF(AS10:AS210="",,IFERROR(AY10:AY210/VLOOKUP(BB10:BB210, _rpe,SUBSTITUTE(AW10:AW210,"+","")+1,FALSE)*1,""))} | BC10: =IFERROR(__xludf.DUMMYFUNCTION("IF(AY10=MAX(FILTER(AY$10:AY$199,LOOKUP(ROW(AS$10:AS$199),FILTER(ROW(AS$10:AS$199),AS$10:AS$199<>AS$9:AS$198))=LOOKUP(ROW(AS10),FILTER(ROW(AS$10:AS$199),AS$10:AS$199<>AS$9:AS$198)))),AZ10,)"),"") | BF10: =IF(ISBLANK(AR10),"",AR10) -> SQ 1: hypertrophy | BG10: =IFERROR(__xludf.DUMMYFUNCTION("ARRAYFORMULA(IF(BI10:BI210="""","""", IF(ISNA(LOOKUP(ROW(BI10:BI210),FILTER(ROW(BI10:BI210),LEN(BI10:BI210)>1),VLOOKUP(FILTER(BI10:BI210,LEN(BI10:BI210)>1),{'Personal Info'!$A:$B;'Personal Info'!$C:$D;'Personal Info'!$E:$F},2,FALSE))), ""ac"" , LOOKUP(ROW"&"(BI10:BI210),FILTER(ROW(BI10:BI210),LEN(BI10:BI210)>1),VLOOKUP(FILTER(BI10:BI210,LEN(BI10:BI210)>1),{'Personal Info'!$A:$B;'Personal Info'!$C:$D;'Personal Info'!$E:$F},2,FALSE)))))"),"sq") -> sq | BH10: {=(AT10+7)*ROW(INDIRECT("A1:A190"))^0} -> 46139 | BI10: =IF(ISBLANK(AU10),"",AU10) -> Competition Squat | BJ10: 3 | BK10: 5 | BL10: 73 | BM10: {=IFERROR(IF(BG10="ac"+ISNUMBER(SEARCH("'",BL10))+BK10="","", IF(ISNUMBER(SEARCH("lw",BL10)), AY10 + SUBSTITUTE(BL10,"lw+",""), MROUND(SWITCH(BG10,"sq",BK$7,"bn",BL$7,"dl",BM$7,"")*IF(BL10>10, BL10/100, VLOOKUP(BL10, _rpe,SUBSTITUTE(BK10,"+","")+1,0)), IF( SWITCH(BG10,"sq",BK$7,"bn",BL$7,"dl", BM$7,"")< IF(_uom="lbs", 175, 80), 1.25, IF(_uom="lbs",5,2.5))))), "")} -> 145 | BN10: {=IF(BG10:BG210="",,IFERROR(BM10:BM210/VLOOKUP(BP10:BP210, _rpe,SUBSTITUTE(BK10:BK210,"+","")+1,FALSE)*1,""))} | BQ10: =IFERROR(__xludf.DUMMYFUNCTION("IF(BM10=MAX(FILTER(BM$10:BM$199,LOOKUP(ROW(BG$10:BG$199),FILTER(ROW(BG$10:BG$199),BG$10:BG$199<>BG$9:BG$198))=LOOKUP(ROW(BG10),FILTER(ROW(BG$10:BG$199),BG$10:BG$199<>BG$9:BG$198)))),BN10,)"),"") | BT10: =IF(ISBLANK(BF10),"",BF10) -> SQ 1: hypertrophy | BU10: =IFERROR(__xludf.DUMMYFUNCTION("ARRAYFORMULA(IF(BW10:BW210="""","""", IF(ISNA(LOOKUP(ROW(BW10:BW210),FILTER(ROW(BW10:BW210),LEN(BW10:BW210)>1),VLOOKUP(FILTER(BW10:BW210,LEN(BW10:BW210)>1),{'Personal Info'!$A:$B;'Personal Info'!$C:$D;'Personal Info'!$E:$F},2,FALSE))), ""ac"" , LOOKUP(ROW"&"(BW10:BW210),FILTER(ROW(BW10:BW210),LEN(BW10:BW210)>1),VLOOKUP(FILTER(BW10:BW210,LEN(BW10:BW210)>1),{'Personal Info'!$A:$B;'Personal Info'!$C:$D;'Personal Info'!$E:$F},2,FALSE)))))"),"sq") -> sq | BV10: {=(BH10+7)*ROW(INDIRECT("A1:A190"))^0} -> 46146 | BW10: =IF(ISBLANK(BI10),"",BI10) -> Competition Squat | BX10: 1 | BY10: 1 | BZ10: @6.5 | CA10: {=IFERROR(IF(BU10="ac"+ISNUMBER(SEARCH("'",BZ10))+BY10="","", IF(ISNUMBER(SEARCH("lw",BZ10)), BM10 + SUBSTITUTE(BZ10,"lw+",""), MROUND(SWITCH(BU10,"sq",BY$7,"bn",BZ$7,"dl",CA$7,"")*IF(BZ10>10, BZ10/100, VLOOKUP(BZ10, _rpe,SUBSTITUTE(BY10,"+","")+1,0)), IF( SWITCH(BU10,"sq",BY$7,"bn",BZ$7,"dl", CA$7,"")< IF(_uom="lbs", 175, 80), 1.25, IF(_uom="lbs",5,2.5))))), "")} | CB10: {=IF(BU10:BU210="",,IFERROR(CA10:CA210/VLOOKUP(CD10:CD210, _rpe,SUBSTITUTE(BY10:BY210,"+","")+1,FALSE)*1,""))} | CE10: =IFERROR(__xludf.DUMMYFUNCTION("IF(CA10=MAX(FILTER(CA$10:CA$199,LOOKUP(ROW(BU$10:BU$199),FILTER(ROW(BU$10:BU$199),BU$10:BU$199<>BU$9:BU$198))=LOOKUP(ROW(BU10),FILTER(ROW(BU$10:BU$199),BU$10:BU$199<>BU$9:BU$198)))),CB10,)"),"") | CH10: =IF(ISBLANK(BT10),"",BT10) -> SQ 1: hypertrophy | CI10: =IFERROR(__xludf.DUMMYFUNCTION("ARRAYFORMULA(IF(CK10:CK210="""","""", IF(ISNA(LOOKUP(ROW(CK10:CK210),FILTER(ROW(CK10:CK210),LEN(CK10:CK210)>1),VLOOKUP(FILTER(CK10:CK210,LEN(CK10:CK210)>1),{'Personal Info'!$A:$B;'Personal Info'!$C:$D;'Personal Info'!$E:$F},2,FALSE))), ""ac"" , LOOKUP(ROW"&"(CK10:CK210),FILTER(ROW(CK10:CK210),LEN(CK10:CK210)>1),VLOOKUP(FILTER(CK10:CK210,LEN(CK10:CK210)>1),{'Personal Info'!$A:$B;'Personal Info'!$C:$D;'Personal Info'!$E:$F},2,FALSE)))))"),"sq") -> sq | CJ10: {=(BV10+7)*ROW(INDIRECT("A1:A190"))^0} -> 46153 | CK10: =IF(ISBLANK(BW10),"",BW10) -> Competition Squat | CL10: =IF(ISBLANK(BX10),"",BX10) -> 1 | CM10: =IF( OR(ISBLANK(BY10),BY10=""),"", BY10) -> 1 | CN10: @7.5 | CO10: {=IFERROR(IF(CI10="ac"+ISNUMBER(SEARCH("'",CN10))+CM10="","", IF(ISNUMBER(SEARCH("lw",CN10)), CA10 + SUBSTITUTE(CN10,"lw+",""), MROUND(SWITCH(CI10,"sq",CM$7,"bn",CN$7,"dl",CO$7,"")*IF(CN10>10, CN10/100, VLOOKUP(CN10, _rpe,SUBSTITUTE(CM10,"+","")+1,0)), IF( SWITCH(CI10,"sq",CM$7,"bn",CN$7,"dl", CO$7,"")< IF(_uom="lbs", 175, 80), 1.25, IF(_uom="lbs",5,2.5))))), "")} | CP10: {=IF(CI10:CI210="",,IFERROR(CO10:CO210/VLOOKUP(CR10:CR210, _rpe,SUBSTITUTE(CM10:CM210,"+","")+1,FALSE)*1,""))} | CS10: =IFERROR(__xludf.DUMMYFUNCTION("IF(CO10=MAX(FILTER(CO$10:CO$199,LOOKUP(ROW(CI$10:CI$199),FILTER(ROW(CI$10:CI$199),CI$10:CI$199<>CI$9:CI$198))=LOOKUP(ROW(CI10),FILTER(ROW(CI$10:CI$199),CI$10:CI$199<>CI$9:CI$198)))),CP10,)"),"") | CV10: =IF(ISBLANK(CH10),"",CH10) -> SQ 1: hypertrophy | CW10: =IFERROR(__xludf.DUMMYFUNCTION("ARRAYFORMULA(IF(CY10:CY210="""","""", IF(ISNA(LOOKUP(ROW(CY10:CY210),FILTER(ROW(CY10:CY210),LEN(CY10:CY210)>1),VLOOKUP(FILTER(CY10:CY210,LEN(CY10:CY210)>1),{'Personal Info'!$A:$B;'Personal Info'!$C:$D;'Personal Info'!$E:$F},2,FALSE))), ""ac"" , LOOKUP(ROW"&"(CY10:CY210),FILTER(ROW(CY10:CY210),LEN(CY10:CY210)>1),VLOOKUP(FILTER(CY10:CY210,LEN(CY10:CY210)>1),{'Personal Info'!$A:$B;'Personal Info'!$C:$D;'Personal Info'!$E:$F},2,FALSE)))))"),"sq") -> sq | CX10: {=(CJ10+7)*ROW(INDIRECT("A1:A190"))^0} -> 46160 | CY10: =IF(ISBLANK(CK10),"",CK10) -> Competition Squat | CZ10: =IF(ISBLANK(CL10),"",CL10) -> 1 | DA10: =IF( OR(ISBLANK(CM10),CM10=""),"", CM10) -> 1 | DB10: @8.5 | DC10: {=IFERROR(IF(CW10="ac"+ISNUMBER(SEARCH("'",DB10))+DA10="","", IF(ISNUMBER(SEARCH("lw",DB10)), CO10 + SUBSTITUTE(DB10,"lw+",""), MROUND(SWITCH(CW10,"sq",DA$7,"bn",DB$7,"dl",DC$7,"")*IF(DB10>10, DB10/100, VLOOKUP(DB10, _rpe,SUBSTITUTE(DA10,"+","")+1,0)), IF( SWITCH(CW10,"sq",DA$7,"bn",DB$7,"dl", DC$7,"")< IF(_uom="lbs", 175, 80), 1.25, IF(_uom="lbs",5,2.5))))), "")} | DD10: {=IF(CW10:CW210="",,IFERROR(DC10:DC210/VLOOKUP(DF10:DF210, _rpe,SUBSTITUTE(DA10:DA210,"+","")+1,FALSE)*1,""))} | DG10: =IFERROR(__xludf.DUMMYFUNCTION("IF(DC10=MAX(FILTER(DC$10:DC$199,LOOKUP(ROW(CW$10:CW$199),FILTER(ROW(CW$10:CW$199),CW$10:CW$199<>CW$9:CW$198))=LOOKUP(ROW(CW10),FILTER(ROW(CW$10:CW$199),CW$10:CW$199<>CW$9:CW$198)))),DD10,)"),"") | DJ10: =IF(ISBLANK(CV10),"",CV10) -> SQ 1: hypertrophy | DK10: =IFERROR(__xludf.DUMMYFUNCTION("ARRAYFORMULA(IF(DM10:DM210="""","""", IF(ISNA(LOOKUP(ROW(DM10:DM210),FILTER(ROW(DM10:DM210),LEN(DM10:DM210)>1),VLOOKUP(FILTER(DM10:DM210,LEN(DM10:DM210)>1),{'Personal Info'!$A:$B;'Personal Info'!$C:$D;'Personal Info'!$E:$F},2,FALSE))), ""ac"" , LOOKUP(ROW"&"(DM10:DM210),FILTER(ROW(DM10:DM210),LEN(DM10:DM210)>1),VLOOKUP(FILTER(DM10:DM210,LEN(DM10:DM210)>1),{'Personal Info'!$A:$B;'Personal Info'!$C:$D;'Personal Info'!$E:$F},2,FALSE)))))"),"sq") -> sq | DL10: {=(CX10+7)*ROW(INDIRECT("A1:A190"))^0} -> 46167 | DM10: Squat | DN10: 5 | DO10: 2 | DP10: 80 | DQ10: {=IFERROR(IF(DK10="ac"+ISNUMBER(SEARCH("'",DP10))+DO10="","", IF(ISNUMBER(SEARCH("lw",DP10)), DC10 + SUBSTITUTE(DP10,"lw+",""), MROUND(SWITCH(DK10,"sq",DO$7,"bn",DP$7,"dl",DQ$7,"")*IF(DP10>10, DP10/100, VLOOKUP(DP10, _rpe,SUBSTITUTE(DO10,"+","")+1,0)), IF( SWITCH(DK10,"sq",DO$7,"bn",DP$7,"dl", DQ$7,"")< IF(_uom="lbs", 175, 80), 1.25, IF(_uom="lbs",5,2.5))))), "")} -> 0 | DR10: {=IF(DK10:DK210="",,IFERROR(DQ10:DQ210/VLOOKUP(DT10:DT210, _rpe,SUBSTITUTE(DO10:DO210,"+","")+1,FALSE)*1,""))} | DU10: =IFERROR(__xludf.DUMMYFUNCTION("IF(DQ10=MAX(FILTER(DQ$10:DQ$199,LOOKUP(ROW(DK$10:DK$199),FILTER(ROW(DK$10:DK$199),DK$10:DK$199<>DK$9:DK$198))=LOOKUP(ROW(DK10),FILTER(ROW(DK$10:DK$199),DK$10:DK$199<>DK$9:DK$198)))),DR10,)"),"") | IW10: =IF(ISBLANK(#REF!),"",#REF!) -> #REF! | IX10: =IFERROR(__xludf.DUMMYFUNCTION("ARRAYFORMULA(IF(#REF!="""","""", IF(ISNA(LOOKUP(ROW(#REF!),FILTER(ROW(#REF!),LEN(#REF!)>1),VLOOKUP(FILTER(#REF!,LEN(#REF!)>1),{'Personal Info'!$A:$B;'Personal Info'!$C:$D;'Personal Info'!$E:$F},2,FALSE))), ""ac"" , LOOKUP(ROW(#REF!),FILTER(ROW(#REF!),LEN("&"#REF!)>1),VLOOKUP(FILTER(#REF!,LEN(#REF!)>1),{'Personal Info'!$A:$B;'Personal Info'!$C:$D;'Personal Info'!$E:$F},2,FALSE)))))"),"#REF!") -> #REF! | IY10: {=(#REF!+7)*ROW(INDIRECT("A1:A190"))^0} -> #REF!
C11: =IFERROR(__xludf.DUMMYFUNCTION("""COMPUTED_VALUE"""),"sq") -> sq | D11: 46111 | E11: - | F11: 3 | G11: 8 | H11: 69 | I11: {=IFERROR(IF(C11="ac"+ISNUMBER(SEARCH("'",H11))+G11="","", MROUND(SWITCH(C11,"sq",'Personal Info'!$O$15,"bn",'Personal Info'!$S$15,"dl",'Personal Info'!$W$15,"")*IF(H11>10, H11/100, VLOOKUP(H11, _rpe,SUBSTITUTE(G11,"+","")+1,0)), IF( SWITCH(C11:C210,"sq",'Personal Info'!$O$15,"bn",'Personal Info'!$S$15,"dl", 'Personal Info'!$W$15,"")< IF(_uom="lbs", 175, 80), 1.25, IF(_uom="lbs",5,2.5)))),"")} -> 140 | M11: =IFERROR(__xludf.DUMMYFUNCTION("IF(I11=MAX(FILTER(I$10:I$199,LOOKUP(ROW(C$10:C$199),FILTER(ROW(C$10:C$199),C$10:C$199<>C$9:C$198))=LOOKUP(ROW(C11),FILTER(ROW(C$10:C$199),C$10:C$199<>C$9:C$198)))),J11,)"),"") | P11: =IF(ISBLANK(B11),"",B11) | Q11: =IFERROR(__xludf.DUMMYFUNCTION("""COMPUTED_VALUE"""),"sq") -> sq | R11: 46118 | S11: =IF(ISBLANK(E11),"",E11) -> - | T11: 3 | U11: 8 | V11: 71 | W11: {=IFERROR(IF(Q11="ac"+ISNUMBER(SEARCH("'",V11))+U11="","", IF(ISNUMBER(SEARCH("lw",V11)), I11 + SUBSTITUTE(V11,"lw+",""), MROUND(SWITCH(Q11,"sq",U$7,"bn",V$7,"dl",W$7,"")*IF(V11>10, V11/100, VLOOKUP(V11, _rpe,SUBSTITUTE(U11,"+","")+1,0)), IF( SWITCH(Q11,"sq",U$7,"bn",V$7,"dl", W$7,"")< IF(_uom="lbs", 175, 80), 1.25, IF(_uom="lbs",5,2.5))))), "")} -> 140 | AA11: =IFERROR(__xludf.DUMMYFUNCTION("IF(W11=MAX(FILTER(W$10:W$199,LOOKUP(ROW(Q$10:Q$199),FILTER(ROW(Q$10:Q$199),Q$10:Q$199<>Q$9:Q$198))=LOOKUP(ROW(Q11),FILTER(ROW(Q$10:Q$199),Q$10:Q$199<>Q$9:Q$198)))),X11,)"),"") | AD11: =IF(ISBLANK(P11),"",P11) | AE11: =IFERROR(__xludf.DUMMYFUNCTION("""COMPUTED_VALUE"""),"sq") -> sq | AF11: 46125 | AG11: =IF(ISBLANK(S11),"",S11) -> - | AH11: =IF(ISBLANK(T11),"",T11) -> 3 | AI11: 7 | AJ11: 73 | AK11: {=IFERROR(IF(AE11="ac"+ISNUMBER(SEARCH("'",AJ11))+AI11="","", IF(ISNUMBER(SEARCH("lw",AJ11)), W11 + SUBSTITUTE(AJ11,"lw+",""), MROUND(SWITCH(AE11,"sq",AI$7,"bn",AJ$7,"dl",AK$7,"")*IF(AJ11>10, AJ11/100, VLOOKUP(AJ11, _rpe,SUBSTITUTE(AI11,"+","")+1,0)), IF( SWITCH(AE11,"sq",AI$7,"bn",AJ$7,"dl", AK$7,"")< IF(_uom="lbs", 175, 80), 1.25, IF(_uom="lbs",5,2.5))))), "")} -> 145 | AO11: =IFERROR(__xludf.DUMMYFUNCTION("IF(AK11=MAX(FILTER(AK$10:AK$199,LOOKUP(ROW(AE$10:AE$199),FILTER(ROW(AE$10:AE$199),AE$10:AE$199<>AE$9:AE$198))=LOOKUP(ROW(AE11),FILTER(ROW(AE$10:AE$199),AE$10:AE$199<>AE$9:AE$198)))),AL11,)"),"") | AR11: =IF(ISBLANK(AD11),"",AD11) | AS11: =IFERROR(__xludf.DUMMYFUNCTION("""COMPUTED_VALUE"""),"sq") -> sq | AT11: 46132 | AU11: =IF(ISBLANK(AG11),"",AG11) -> - | AV11: 3 | AW11: 7 | AX11: 75 | AY11: {=IFERROR(IF(AS11="ac"+ISNUMBER(SEARCH("'",AX11))+AW11="","", IF(ISNUMBER(SEARCH("lw",AX11)), AK11 + SUBSTITUTE(AX11,"lw+",""), MROUND(SWITCH(AS11,"sq",AW$7,"bn",AX$7,"dl",AY$7,"")*IF(AX11>10, AX11/100, VLOOKUP(AX11, _rpe,SUBSTITUTE(AW11,"+","")+1,0)), IF( SWITCH(AS11,"sq",AW$7,"bn",AX$7,"dl", AY$7,"")< IF(_uom="lbs", 175, 80), 1.25, IF(_uom="lbs",5,2.5))))), "")} -> 150 | BC11: =IFERROR(__xludf.DUMMYFUNCTION("IF(AY11=MAX(FILTER(AY$10:AY$199,LOOKUP(ROW(AS$10:AS$199),FILTER(ROW(AS$10:AS$199),AS$10:AS$199<>AS$9:AS$198))=LOOKUP(ROW(AS11),FILTER(ROW(AS$10:AS$199),AS$10:AS$199<>AS$9:AS$198)))),AZ11,)"),"") | BF11: =IF(ISBLANK(AR11),"",AR11) | BG11: =IFERROR(__xludf.DUMMYFUNCTION("""COMPUTED_VALUE"""),"sq") -> sq | BH11: 46139 | BI11: =IF(ISBLANK(AU11),"",AU11) -> - | BM11: {=IFERROR(IF(BG11="ac"+ISNUMBER(SEARCH("'",BL11))+BK11="","", IF(ISNUMBER(SEARCH("lw",BL11)), AY11 + SUBSTITUTE(BL11,"lw+",""), MROUND(SWITCH(BG11,"sq",BK$7,"bn",BL$7,"dl",BM$7,"")*IF(BL11>10, BL11/100, VLOOKUP(BL11, _rpe,SUBSTITUTE(BK11,"+","")+1,0)), IF( SWITCH(BG11,"sq",BK$7,"bn",BL$7,"dl", BM$7,"")< IF(_uom="lbs", 175, 80), 1.25, IF(_uom="lbs",5,2.5))))), "")} | BQ11: =IFERROR(__xludf.DUMMYFUNCTION("IF(BM11=MAX(FILTER(BM$10:BM$199,LOOKUP(ROW(BG$10:BG$199),FILTER(ROW(BG$10:BG$199),BG$10:BG$199<>BG$9:BG$198))=LOOKUP(ROW(BG11),FILTER(ROW(BG$10:BG$199),BG$10:BG$199<>BG$9:BG$198)))),BN11,)"),"") | BT11: =IF(ISBLANK(BF11),"",BF11) | BU11: =IFERROR(__xludf.DUMMYFUNCTION("""COMPUTED_VALUE"""),"sq") -> sq | BV11: 46146 | BW11: =IF(ISBLANK(BI11),"",BI11) -> - | BX11: 5 | BY11: 3 | BZ11: 85 | CA11: {=IFERROR(IF(BU11="ac"+ISNUMBER(SEARCH("'",BZ11))+BY11="","", IF(ISNUMBER(SEARCH("lw",BZ11)), BM11 + SUBSTITUTE(BZ11,"lw+",""), MROUND(SWITCH(BU11,"sq",BY$7,"bn",BZ$7,"dl",CA$7,"")*IF(BZ11>10, BZ11/100, VLOOKUP(BZ11, _rpe,SUBSTITUTE(BY11,"+","")+1,0)), IF( SWITCH(BU11,"sq",BY$7,"bn",BZ$7,"dl", CA$7,"")< IF(_uom="lbs", 175, 80), 1.25, IF(_uom="lbs",5,2.5))))), "")} -> 170 | CE11: =IFERROR(__xludf.DUMMYFUNCTION("IF(CA11=MAX(FILTER(CA$10:CA$199,LOOKUP(ROW(BU$10:BU$199),FILTER(ROW(BU$10:BU$199),BU$10:BU$199<>BU$9:BU$198))=LOOKUP(ROW(BU11),FILTER(ROW(BU$10:BU$199),BU$10:BU$199<>BU$9:BU$198)))),CB11,)"),"") | CH11: =IF(ISBLANK(BT11),"",BT11) | CI11: =IFERROR(__xludf.DUMMYFUNCTION("""COMPUTED_VALUE"""),"sq") -> sq | CJ11: 46153 | CK11: =IF(ISBLANK(BW11),"",BW11) -> - | CL11: 5 | CM11: 3 | CN11: 87 | CO11: {=IFERROR(IF(CI11="ac"+ISNUMBER(SEARCH("'",CN11))+CM11="","", IF(ISNUMBER(SEARCH("lw",CN11)), CA11 + SUBSTITUTE(CN11,"lw+",""), MROUND(SWITCH(CI11,"sq",CM$7,"bn",CN$7,"dl",CO$7,"")*IF(CN11>10, CN11/100, VLOOKUP(CN11, _rpe,SUBSTITUTE(CM11,"+","")+1,0)), IF( SWITCH(CI11,"sq",CM$7,"bn",CN$7,"dl", CO$7,"")< IF(_uom="lbs", 175, 80), 1.25, IF(_uom="lbs",5,2.5))))), "")} -> 175 | CS11: =IFERROR(__xludf.DUMMYFUNCTION("IF(CO11=MAX(FILTER(CO$10:CO$199,LOOKUP(ROW(CI$10:CI$199),FILTER(ROW(CI$10:CI$199),CI$10:CI$199<>CI$9:CI$198))=LOOKUP(ROW(CI11),FILTER(ROW(CI$10:CI$199),CI$10:CI$199<>CI$9:CI$198)))),CP11,)"),"") | CV11: =IF(ISBLANK(CH11),"",CH11) | CW11: =IFERROR(__xludf.DUMMYFUNCTION("""COMPUTED_VALUE"""),"sq") -> sq | CX11: 46160 | CY11: =IF(ISBLANK(CK11),"",CK11) -> - | CZ11: 5 | DA11: 2 | DB11: 89 | DC11: {=IFERROR(IF(CW11="ac"+ISNUMBER(SEARCH("'",DB11))+DA11="","", IF(ISNUMBER(SEARCH("lw",DB11)), CO11 + SUBSTITUTE(DB11,"lw+",""), MROUND(SWITCH(CW11,"sq",DA$7,"bn",DB$7,"dl",DC$7,"")*IF(DB11>10, DB11/100, VLOOKUP(DB11, _rpe,SUBSTITUTE(DA11,"+","")+1,0)), IF( SWITCH(CW11,"sq",DA$7,"bn",DB$7,"dl", DC$7,"")< IF(_uom="lbs", 175, 80), 1.25, IF(_uom="lbs",5,2.5))))), "")} -> 180 | DG11: =IFERROR(__xludf.DUMMYFUNCTION("IF(DC11=MAX(FILTER(DC$10:DC$199,LOOKUP(ROW(CW$10:CW$199),FILTER(ROW(CW$10:CW$199),CW$10:CW$199<>CW$9:CW$198))=LOOKUP(ROW(CW11),FILTER(ROW(CW$10:CW$199),CW$10:CW$199<>CW$9:CW$198)))),DD11,)"),"") | DJ11: =IF(ISBLANK(CV11),"",CV11) | DK11: =IFERROR(__xludf.DUMMYFUNCTION("""COMPUTED_VALUE"""),"sq") -> sq | DL11: 46167 | DM11: =IF(ISBLANK(CY11),"",CY11) -> - | DQ11: {=IFERROR(IF(DK11="ac"+ISNUMBER(SEARCH("'",DP11))+DO11="","", IF(ISNUMBER(SEARCH("lw",DP11)), DC11 + SUBSTITUTE(DP11,"lw+",""), MROUND(SWITCH(DK11,"sq",DO$7,"bn",DP$7,"dl",DQ$7,"")*IF(DP11>10, DP11/100, VLOOKUP(DP11, _rpe,SUBSTITUTE(DO11,"+","")+1,0)), IF( SWITCH(DK11,"sq",DO$7,"bn",DP$7,"dl", DQ$7,"")< IF(_uom="lbs", 175, 80), 1.25, IF(_uom="lbs",5,2.5))))), "")} | DU11: =IFERROR(__xludf.DUMMYFUNCTION("IF(DQ11=MAX(FILTER(DQ$10:DQ$199,LOOKUP(ROW(DK$10:DK$199),FILTER(ROW(DK$10:DK$199),DK$10:DK$199<>DK$9:DK$198))=LOOKUP(ROW(DK11),FILTER(ROW(DK$10:DK$199),DK$10:DK$199<>DK$9:DK$198)))),DR11,)"),"") | IW11: =IF(ISBLANK(#REF!),"",#REF!) -> #REF! | IY11: #REF!
C12: =IFERROR(__xludf.DUMMYFUNCTION("""COMPUTED_VALUE"""),"") | D12: 46111 | I12: {=IFERROR(IF(C12="ac"+ISNUMBER(SEARCH("'",H12))+G12="","", MROUND(SWITCH(C12,"sq",'Personal Info'!$O$15,"bn",'Personal Info'!$S$15,"dl",'Personal Info'!$W$15,"")*IF(H12>10, H12/100, VLOOKUP(H12, _rpe,SUBSTITUTE(G12,"+","")+1,0)), IF( SWITCH(C12:C210,"sq",'Personal Info'!$O$15,"bn",'Personal Info'!$S$15,"dl", 'Personal Info'!$W$15,"")< IF(_uom="lbs", 175, 80), 1.25, IF(_uom="lbs",5,2.5)))),"")} | M12: =IFERROR(__xludf.DUMMYFUNCTION("IF(I12=MAX(FILTER(I$10:I$199,LOOKUP(ROW(C$10:C$199),FILTER(ROW(C$10:C$199),C$10:C$199<>C$9:C$198))=LOOKUP(ROW(C12),FILTER(ROW(C$10:C$199),C$10:C$199<>C$9:C$198)))),J12,)"),"") | P12: =IF(ISBLANK(B12),"",B12) | Q12: =IFERROR(__xludf.DUMMYFUNCTION("""COMPUTED_VALUE"""),"") | R12: 46118 | S12: =IF(ISBLANK(E12),"",E12) | T12: =IF(ISBLANK(F12),"",F12) | U12: =IF( OR(ISBLANK(G12),G12=""),"", G12) | V12: =IF(ISBLANK(H12),"",H12) | W12: {=IFERROR(IF(Q12="ac"+ISNUMBER(SEARCH("'",V12))+U12="","", IF(ISNUMBER(SEARCH("lw",V12)), I12 + SUBSTITUTE(V12,"lw+",""), MROUND(SWITCH(Q12,"sq",U$7,"bn",V$7,"dl",W$7,"")*IF(V12>10, V12/100, VLOOKUP(V12, _rpe,SUBSTITUTE(U12,"+","")+1,0)), IF( SWITCH(Q12,"sq",U$7,"bn",V$7,"dl", W$7,"")< IF(_uom="lbs", 175, 80), 1.25, IF(_uom="lbs",5,2.5))))), "")} | AA12: =IFERROR(__xludf.DUMMYFUNCTION("IF(W12=MAX(FILTER(W$10:W$199,LOOKUP(ROW(Q$10:Q$199),FILTER(ROW(Q$10:Q$199),Q$10:Q$199<>Q$9:Q$198))=LOOKUP(ROW(Q12),FILTER(ROW(Q$10:Q$199),Q$10:Q$199<>Q$9:Q$198)))),X12,)"),"") | AD12: =IF(ISBLANK(P12),"",P12) | AE12: =IFERROR(__xludf.DUMMYFUNCTION("""COMPUTED_VALUE"""),"") | AF12: 46125 | AG12: =IF(ISBLANK(S12),"",S12) | AH12: =IF(ISBLANK(T12),"",T12) | AI12: =IF( OR(ISBLANK(U12),U12=""),"", U12) | AJ12: =IF(ISBLANK(V12),"",V12) | AK12: {=IFERROR(IF(AE12="ac"+ISNUMBER(SEARCH("'",AJ12))+AI12="","", IF(ISNUMBER(SEARCH("lw",AJ12)), W12 + SUBSTITUTE(AJ12,"lw+",""), MROUND(SWITCH(AE12,"sq",AI$7,"bn",AJ$7,"dl",AK$7,"")*IF(AJ12>10, AJ12/100, VLOOKUP(AJ12, _rpe,SUBSTITUTE(AI12,"+","")+1,0)), IF( SWITCH(AE12,"sq",AI$7,"bn",AJ$7,"dl", AK$7,"")< IF(_uom="lbs", 175, 80), 1.25, IF(_uom="lbs",5,2.5))))), "")} | AO12: =IFERROR(__xludf.DUMMYFUNCTION("IF(AK12=MAX(FILTER(AK$10:AK$199,LOOKUP(ROW(AE$10:AE$199),FILTER(ROW(AE$10:AE$199),AE$10:AE$199<>AE$9:AE$198))=LOOKUP(ROW(AE12),FILTER(ROW(AE$10:AE$199),AE$10:AE$199<>AE$9:AE$198)))),AL12,)"),"") | AR12: =IF(ISBLANK(AD12),"",AD12) | AS12: =IFERROR(__xludf.DUMMYFUNCTION("""COMPUTED_VALUE"""),"") | AT12: 46132 | AU12: =IF(ISBLANK(AG12),"",AG12) | AV12: =IF(ISBLANK(AH12),"",AH12) | AW12: =IF( OR(ISBLANK(AI12),AI12=""),"", AI12) | AX12: =IF(ISBLANK(AJ12),"",AJ12) | AY12: {=IFERROR(IF(AS12="ac"+ISNUMBER(SEARCH("'",AX12))+AW12="","", IF(ISNUMBER(SEARCH("lw",AX12)), AK12 + SUBSTITUTE(AX12,"lw+",""), MROUND(SWITCH(AS12,"sq",AW$7,"bn",AX$7,"dl",AY$7,"")*IF(AX12>10, AX12/100, VLOOKUP(AX12, _rpe,SUBSTITUTE(AW12,"+","")+1,0)), IF( SWITCH(AS12,"sq",AW$7,"bn",AX$7,"dl", AY$7,"")< IF(_uom="lbs", 175, 80), 1.25, IF(_uom="lbs",5,2.5))))), "")} | BC12: =IFERROR(__xludf.DUMMYFUNCTION("IF(AY12=MAX(FILTER(AY$10:AY$199,LOOKUP(ROW(AS$10:AS$199),FILTER(ROW(AS$10:AS$199),AS$10:AS$199<>AS$9:AS$198))=LOOKUP(ROW(AS12),FILTER(ROW(AS$10:AS$199),AS$10:AS$199<>AS$9:AS$198)))),AZ12,)"),"") | BF12: =IF(ISBLANK(AR12),"",AR12) | BG12: =IFERROR(__xludf.DUMMYFUNCTION("""COMPUTED_VALUE"""),"") | BH12: 46139 | BI12: =IF(ISBLANK(AU12),"",AU12) | BJ12: =IF(ISBLANK(AV12),"",AV12) | BK12: =IF( OR(ISBLANK(AW12),AW12=""),"", AW12) | BL12: =IF(ISBLANK(AX12),"",AX12) | BM12: {=IFERROR(IF(BG12="ac"+ISNUMBER(SEARCH("'",BL12))+BK12="","", IF(ISNUMBER(SEARCH("lw",BL12)), AY12 + SUBSTITUTE(BL12,"lw+",""), MROUND(SWITCH(BG12,"sq",BK$7,"bn",BL$7,"dl",BM$7,"")*IF(BL12>10, BL12/100, VLOOKUP(BL12, _rpe,SUBSTITUTE(BK12,"+","")+1,0)), IF( SWITCH(BG12,"sq",BK$7,"bn",BL$7,"dl", BM$7,"")< IF(_uom="lbs", 175, 80), 1.25, IF(_uom="lbs",5,2.5))))), "")} | BQ12: =IFERROR(__xludf.DUMMYFUNCTION("IF(BM12=MAX(FILTER(BM$10:BM$199,LOOKUP(ROW(BG$10:BG$199),FILTER(ROW(BG$10:BG$199),BG$10:BG$199<>BG$9:BG$198))=LOOKUP(ROW(BG12),FILTER(ROW(BG$10:BG$199),BG$10:BG$199<>BG$9:BG$198)))),BN12,)"),"") | BT12: =IF(ISBLANK(BF12),"",BF12) | BU12: =IFERROR(__xludf.DUMMYFUNCTION("""COMPUTED_VALUE"""),"") | BV12: 46146 | BW12: =IF(ISBLANK(BI12),"",BI12) | BX12: =IF(ISBLANK(BJ12),"",BJ12) | BY12: =IF( OR(ISBLANK(BK12),BK12=""),"", BK12) | BZ12: =IF(ISBLANK(BL12),"",BL12) | CA12: {=IFERROR(IF(BU12="ac"+ISNUMBER(SEARCH("'",BZ12))+BY12="","", IF(ISNUMBER(SEARCH("lw",BZ12)), BM12 + SUBSTITUTE(BZ12,"lw+",""), MROUND(SWITCH(BU12,"sq",BY$7,"bn",BZ$7,"dl",CA$7,"")*IF(BZ12>10, BZ12/100, VLOOKUP(BZ12, _rpe,SUBSTITUTE(BY12,"+","")+1,0)), IF( SWITCH(BU12,"sq",BY$7,"bn",BZ$7,"dl", CA$7,"")< IF(_uom="lbs", 175, 80), 1.25, IF(_uom="lbs",5,2.5))))), "")} | CE12: =IFERROR(__xludf.DUMMYFUNCTION("IF(CA12=MAX(FILTER(CA$10:CA$199,LOOKUP(ROW(BU$10:BU$199),FILTER(ROW(BU$10:BU$199),BU$10:BU$199<>BU$9:BU$198))=LOOKUP(ROW(BU12),FILTER(ROW(BU$10:BU$199),BU$10:BU$199<>BU$9:BU$198)))),CB12,)"),"") | CH12: =IF(ISBLANK(BT12),"",BT12) | CI12: =IFERROR(__xludf.DUMMYFUNCTION("""COMPUTED_VALUE"""),"") | CJ12: 46153 | CK12: =IF(ISBLANK(BW12),"",BW12) | CL12: =IF(ISBLANK(BX12),"",BX12) | CM12: =IF( OR(ISBLANK(BY12),BY12=""),"", BY12) | CN12: =IF(ISBLANK(BZ12),"",BZ12) | CO12: {=IFERROR(IF(CI12="ac"+ISNUMBER(SEARCH("'",CN12))+CM12="","", IF(ISNUMBER(SEARCH("lw",CN12)), CA12 + SUBSTITUTE(CN12,"lw+",""), MROUND(SWITCH(CI12,"sq",CM$7,"bn",CN$7,"dl",CO$7,"")*IF(CN12>10, CN12/100, VLOOKUP(CN12, _rpe,SUBSTITUTE(CM12,"+","")+1,0)), IF( SWITCH(CI12,"sq",CM$7,"bn",CN$7,"dl", CO$7,"")< IF(_uom="lbs", 175, 80), 1.25, IF(_uom="lbs",5,2.5))))), "")} | CS12: =IFERROR(__xludf.DUMMYFUNCTION("IF(CO12=MAX(FILTER(CO$10:CO$199,LOOKUP(ROW(CI$10:CI$199),FILTER(ROW(CI$10:CI$199),CI$10:CI$199<>CI$9:CI$198))=LOOKUP(ROW(CI12),FILTER(ROW(CI$10:CI$199),CI$10:CI$199<>CI$9:CI$198)))),CP12,)"),"") | CV12: =IF(ISBLANK(CH12),"",CH12) | CW12: =IFERROR(__xludf.DUMMYFUNCTION("""COMPUTED_VALUE"""),"") | CX12: 46160 | CY12: =IF(ISBLANK(CK12),"",CK12) | CZ12: =IF(ISBLANK(CL12),"",CL12) | DA12: =IF( OR(ISBLANK(CM12),CM12=""),"", CM12) | DB12: =IF(ISBLANK(CN12),"",CN12) | DC12: {=IFERROR(IF(CW12="ac"+ISNUMBER(SEARCH("'",DB12))+DA12="","", IF(ISNUMBER(SEARCH("lw",DB12)), CO12 + SUBSTITUTE(DB12,"lw+",""), MROUND(SWITCH(CW12,"sq",DA$7,"bn",DB$7,"dl",DC$7,"")*IF(DB12>10, DB12/100, VLOOKUP(DB12, _rpe,SUBSTITUTE(DA12,"+","")+1,0)), IF( SWITCH(CW12,"sq",DA$7,"bn",DB$7,"dl", DC$7,"")< IF(_uom="lbs", 175, 80), 1.25, IF(_uom="lbs",5,2.5))))), "")} | DG12: =IFERROR(__xludf.DUMMYFUNCTION("IF(DC12=MAX(FILTER(DC$10:DC$199,LOOKUP(ROW(CW$10:CW$199),FILTER(ROW(CW$10:CW$199),CW$10:CW$199<>CW$9:CW$198))=LOOKUP(ROW(CW12),FILTER(ROW(CW$10:CW$199),CW$10:CW$199<>CW$9:CW$198)))),DD12,)"),"") | DJ12: =IF(ISBLANK(CV12),"",CV12) | DK12: =IFERROR(__xludf.DUMMYFUNCTION("""COMPUTED_VALUE"""),"") | DL12: 46167 | DM12: =IF(ISBLANK(CY12),"",CY12) | DN12: =IF(ISBLANK(CZ12),"",CZ12) | DO12: =IF( OR(ISBLANK(DA12),DA12=""),"", DA12) | DP12: =IF(ISBLANK(DB12),"",DB12) | DQ12: {=IFERROR(IF(DK12="ac"+ISNUMBER(SEARCH("'",DP12))+DO12="","", IF(ISNUMBER(SEARCH("lw",DP12)), DC12 + SUBSTITUTE(DP12,"lw+",""), MROUND(SWITCH(DK12,"sq",DO$7,"bn",DP$7,"dl",DQ$7,"")*IF(DP12>10, DP12/100, VLOOKUP(DP12, _rpe,SUBSTITUTE(DO12,"+","")+1,0)), IF( SWITCH(DK12,"sq",DO$7,"bn",DP$7,"dl", DQ$7,"")< IF(_uom="lbs", 175, 80), 1.25, IF(_uom="lbs",5,2.5))))), "")} | DU12: =IFERROR(__xludf.DUMMYFUNCTION("IF(DQ12=MAX(FILTER(DQ$10:DQ$199,LOOKUP(ROW(DK$10:DK$199),FILTER(ROW(DK$10:DK$199),DK$10:DK$199<>DK$9:DK$198))=LOOKUP(ROW(DK12),FILTER(ROW(DK$10:DK$199),DK$10:DK$199<>DK$9:DK$198)))),DR12,)"),"") | IW12: =IF(ISBLANK(#REF!),"",#REF!) -> #REF! | IY12: #REF!
C13: =IFERROR(__xludf.DUMMYFUNCTION("""COMPUTED_VALUE"""),"") | D13: 46111 | I13: {=IFERROR(IF(C13="ac"+ISNUMBER(SEARCH("'",H13))+G13="","", MROUND(SWITCH(C13,"sq",'Personal Info'!$O$15,"bn",'Personal Info'!$S$15,"dl",'Personal Info'!$W$15,"")*IF(H13>10, H13/100, VLOOKUP(H13, _rpe,SUBSTITUTE(G13,"+","")+1,0)), IF( SWITCH(C13:C210,"sq",'Personal Info'!$O$15,"bn",'Personal Info'!$S$15,"dl", 'Personal Info'!$W$15,"")< IF(_uom="lbs", 175, 80), 1.25, IF(_uom="lbs",5,2.5)))),"")} | M13: =IFERROR(__xludf.DUMMYFUNCTION("IF(I13=MAX(FILTER(I$10:I$199,LOOKUP(ROW(C$10:C$199),FILTER(ROW(C$10:C$199),C$10:C$199<>C$9:C$198))=LOOKUP(ROW(C13),FILTER(ROW(C$10:C$199),C$10:C$199<>C$9:C$198)))),J13,)"),"") | P13: =IF(ISBLANK(B13),"",B13) | Q13: =IFERROR(__xludf.DUMMYFUNCTION("""COMPUTED_VALUE"""),"") | R13: 46118 | S13: =IF(ISBLANK(E13),"",E13) | T13: =IF(ISBLANK(F13),"",F13) | U13: =IF( OR(ISBLANK(G13),G13=""),"", G13) | V13: =IF(ISBLANK(H13),"",H13) | W13: {=IFERROR(IF(Q13="ac"+ISNUMBER(SEARCH("'",V13))+U13="","", IF(ISNUMBER(SEARCH("lw",V13)), I13 + SUBSTITUTE(V13,"lw+",""), MROUND(SWITCH(Q13,"sq",U$7,"bn",V$7,"dl",W$7,"")*IF(V13>10, V13/100, VLOOKUP(V13, _rpe,SUBSTITUTE(U13,"+","")+1,0)), IF( SWITCH(Q13,"sq",U$7,"bn",V$7,"dl", W$7,"")< IF(_uom="lbs", 175, 80), 1.25, IF(_uom="lbs",5,2.5))))), "")} | AA13: =IFERROR(__xludf.DUMMYFUNCTION("IF(W13=MAX(FILTER(W$10:W$199,LOOKUP(ROW(Q$10:Q$199),FILTER(ROW(Q$10:Q$199),Q$10:Q$199<>Q$9:Q$198))=LOOKUP(ROW(Q13),FILTER(ROW(Q$10:Q$199),Q$10:Q$199<>Q$9:Q$198)))),X13,)"),"") | AD13: =IF(ISBLANK(P13),"",P13) | AE13: =IFERROR(__xludf.DUMMYFUNCTION("""COMPUTED_VALUE"""),"") | AF13: 46125 | AG13: =IF(ISBLANK(S13),"",S13) | AH13: =IF(ISBLANK(T13),"",T13) | AI13: =IF( OR(ISBLANK(U13),U13=""),"", U13) | AJ13: =IF(ISBLANK(V13),"",V13) | AK13: {=IFERROR(IF(AE13="ac"+ISNUMBER(SEARCH("'",AJ13))+AI13="","", IF(ISNUMBER(SEARCH("lw",AJ13)), W13 + SUBSTITUTE(AJ13,"lw+",""), MROUND(SWITCH(AE13,"sq",AI$7,"bn",AJ$7,"dl",AK$7,"")*IF(AJ13>10, AJ13/100, VLOOKUP(AJ13, _rpe,SUBSTITUTE(AI13,"+","")+1,0)), IF( SWITCH(AE13,"sq",AI$7,"bn",AJ$7,"dl", AK$7,"")< IF(_uom="lbs", 175, 80), 1.25, IF(_uom="lbs",5,2.5))))), "")} | AO13: =IFERROR(__xludf.DUMMYFUNCTION("IF(AK13=MAX(FILTER(AK$10:AK$199,LOOKUP(ROW(AE$10:AE$199),FILTER(ROW(AE$10:AE$199),AE$10:AE$199<>AE$9:AE$198))=LOOKUP(ROW(AE13),FILTER(ROW(AE$10:AE$199),AE$10:AE$199<>AE$9:AE$198)))),AL13,)"),"") | AR13: =IF(ISBLANK(AD13),"",AD13) | AS13: =IFERROR(__xludf.DUMMYFUNCTION("""COMPUTED_VALUE"""),"") | AT13: 46132 | AU13: =IF(ISBLANK(AG13),"",AG13) | AV13: =IF(ISBLANK(AH13),"",AH13) | AW13: =IF( OR(ISBLANK(AI13),AI13=""),"", AI13) | AX13: =IF(ISBLANK(AJ13),"",AJ13) | AY13: {=IFERROR(IF(AS13="ac"+ISNUMBER(SEARCH("'",AX13))+AW13="","", IF(ISNUMBER(SEARCH("lw",AX13)), AK13 + SUBSTITUTE(AX13,"lw+",""), MROUND(SWITCH(AS13,"sq",AW$7,"bn",AX$7,"dl",AY$7,"")*IF(AX13>10, AX13/100, VLOOKUP(AX13, _rpe,SUBSTITUTE(AW13,"+","")+1,0)), IF( SWITCH(AS13,"sq",AW$7,"bn",AX$7,"dl", AY$7,"")< IF(_uom="lbs", 175, 80), 1.25, IF(_uom="lbs",5,2.5))))), "")} | BC13: =IFERROR(__xludf.DUMMYFUNCTION("IF(AY13=MAX(FILTER(AY$10:AY$199,LOOKUP(ROW(AS$10:AS$199),FILTER(ROW(AS$10:AS$199),AS$10:AS$199<>AS$9:AS$198))=LOOKUP(ROW(AS13),FILTER(ROW(AS$10:AS$199),AS$10:AS$199<>AS$9:AS$198)))),AZ13,)"),"") | BF13: =IF(ISBLANK(AR13),"",AR13) | BG13: =IFERROR(__xludf.DUMMYFUNCTION("""COMPUTED_VALUE"""),"") | BH13: 46139 | BI13: =IF(ISBLANK(AU13),"",AU13) | BJ13: =IF(ISBLANK(AV13),"",AV13) | BK13: =IF( OR(ISBLANK(AW13),AW13=""),"", AW13) | BL13: =IF(ISBLANK(AX13),"",AX13) | BM13: {=IFERROR(IF(BG13="ac"+ISNUMBER(SEARCH("'",BL13))+BK13="","", IF(ISNUMBER(SEARCH("lw",BL13)), AY13 + SUBSTITUTE(BL13,"lw+",""), MROUND(SWITCH(BG13,"sq",BK$7,"bn",BL$7,"dl",BM$7,"")*IF(BL13>10, BL13/100, VLOOKUP(BL13, _rpe,SUBSTITUTE(BK13,"+","")+1,0)), IF( SWITCH(BG13,"sq",BK$7,"bn",BL$7,"dl", BM$7,"")< IF(_uom="lbs", 175, 80), 1.25, IF(_uom="lbs",5,2.5))))), "")} | BQ13: =IFERROR(__xludf.DUMMYFUNCTION("IF(BM13=MAX(FILTER(BM$10:BM$199,LOOKUP(ROW(BG$10:BG$199),FILTER(ROW(BG$10:BG$199),BG$10:BG$199<>BG$9:BG$198))=LOOKUP(ROW(BG13),FILTER(ROW(BG$10:BG$199),BG$10:BG$199<>BG$9:BG$198)))),BN13,)"),"") | BT13: =IF(ISBLANK(BF13),"",BF13) | BU13: =IFERROR(__xludf.DUMMYFUNCTION("""COMPUTED_VALUE"""),"") | BV13: 46146 | BW13: =IF(ISBLANK(BI13),"",BI13) | BX13: =IF(ISBLANK(BJ13),"",BJ13) | BY13: =IF( OR(ISBLANK(BK13),BK13=""),"", BK13) | BZ13: =IF(ISBLANK(BL13),"",BL13) | CA13: {=IFERROR(IF(BU13="ac"+ISNUMBER(SEARCH("'",BZ13))+BY13="","", IF(ISNUMBER(SEARCH("lw",BZ13)), BM13 + SUBSTITUTE(BZ13,"lw+",""), MROUND(SWITCH(BU13,"sq",BY$7,"bn",BZ$7,"dl",CA$7,"")*IF(BZ13>10, BZ13/100, VLOOKUP(BZ13, _rpe,SUBSTITUTE(BY13,"+","")+1,0)), IF( SWITCH(BU13,"sq",BY$7,"bn",BZ$7,"dl", CA$7,"")< IF(_uom="lbs", 175, 80), 1.25, IF(_uom="lbs",5,2.5))))), "")} | CE13: =IFERROR(__xludf.DUMMYFUNCTION("IF(CA13=MAX(FILTER(CA$10:CA$199,LOOKUP(ROW(BU$10:BU$199),FILTER(ROW(BU$10:BU$199),BU$10:BU$199<>BU$9:BU$198))=LOOKUP(ROW(BU13),FILTER(ROW(BU$10:BU$199),BU$10:BU$199<>BU$9:BU$198)))),CB13,)"),"") | CH13: =IF(ISBLANK(BT13),"",BT13) | CI13: =IFERROR(__xludf.DUMMYFUNCTION("""COMPUTED_VALUE"""),"") | CJ13: 46153 | CK13: =IF(ISBLANK(BW13),"",BW13) | CL13: =IF(ISBLANK(BX13),"",BX13) | CM13: =IF( OR(ISBLANK(BY13),BY13=""),"", BY13) | CN13: =IF(ISBLANK(BZ13),"",BZ13) | CO13: {=IFERROR(IF(CI13="ac"+ISNUMBER(SEARCH("'",CN13))+CM13="","", IF(ISNUMBER(SEARCH("lw",CN13)), CA13 + SUBSTITUTE(CN13,"lw+",""), MROUND(SWITCH(CI13,"sq",CM$7,"bn",CN$7,"dl",CO$7,"")*IF(CN13>10, CN13/100, VLOOKUP(CN13, _rpe,SUBSTITUTE(CM13,"+","")+1,0)), IF( SWITCH(CI13,"sq",CM$7,"bn",CN$7,"dl", CO$7,"")< IF(_uom="lbs", 175, 80), 1.25, IF(_uom="lbs",5,2.5))))), "")} | CS13: =IFERROR(__xludf.DUMMYFUNCTION("IF(CO13=MAX(FILTER(CO$10:CO$199,LOOKUP(ROW(CI$10:CI$199),FILTER(ROW(CI$10:CI$199),CI$10:CI$199<>CI$9:CI$198))=LOOKUP(ROW(CI13),FILTER(ROW(CI$10:CI$199),CI$10:CI$199<>CI$9:CI$198)))),CP13,)"),"") | CV13: =IF(ISBLANK(CH13),"",CH13) | CW13: =IFERROR(__xludf.DUMMYFUNCTION("""COMPUTED_VALUE"""),"") | CX13: 46160 | CY13: =IF(ISBLANK(CK13),"",CK13) | CZ13: =IF(ISBLANK(CL13),"",CL13) | DA13: =IF( OR(ISBLANK(CM13),CM13=""),"", CM13) | DB13: =IF(ISBLANK(CN13),"",CN13) | DC13: {=IFERROR(IF(CW13="ac"+ISNUMBER(SEARCH("'",DB13))+DA13="","", IF(ISNUMBER(SEARCH("lw",DB13)), CO13 + SUBSTITUTE(DB13,"lw+",""), MROUND(SWITCH(CW13,"sq",DA$7,"bn",DB$7,"dl",DC$7,"")*IF(DB13>10, DB13/100, VLOOKUP(DB13, _rpe,SUBSTITUTE(DA13,"+","")+1,0)), IF( SWITCH(CW13,"sq",DA$7,"bn",DB$7,"dl", DC$7,"")< IF(_uom="lbs", 175, 80), 1.25, IF(_uom="lbs",5,2.5))))), "")} | DG13: =IFERROR(__xludf.DUMMYFUNCTION("IF(DC13=MAX(FILTER(DC$10:DC$199,LOOKUP(ROW(CW$10:CW$199),FILTER(ROW(CW$10:CW$199),CW$10:CW$199<>CW$9:CW$198))=LOOKUP(ROW(CW13),FILTER(ROW(CW$10:CW$199),CW$10:CW$199<>CW$9:CW$198)))),DD13,)"),"") | DJ13: =IF(ISBLANK(CV13),"",CV13) | DK13: =IFERROR(__xludf.DUMMYFUNCTION("""COMPUTED_VALUE"""),"") | DL13: 46167 | DM13: =IF(ISBLANK(CY13),"",CY13) | DN13: =IF(ISBLANK(CZ13),"",CZ13) | DO13: =IF( OR(ISBLANK(DA13),DA13=""),"", DA13) | DP13: =IF(ISBLANK(DB13),"",DB13) | DQ13: {=IFERROR(IF(DK13="ac"+ISNUMBER(SEARCH("'",DP13))+DO13="","", IF(ISNUMBER(SEARCH("lw",DP13)), DC13 + SUBSTITUTE(DP13,"lw+",""), MROUND(SWITCH(DK13,"sq",DO$7,"bn",DP$7,"dl",DQ$7,"")*IF(DP13>10, DP13/100, VLOOKUP(DP13, _rpe,SUBSTITUTE(DO13,"+","")+1,0)), IF( SWITCH(DK13,"sq",DO$7,"bn",DP$7,"dl", DQ$7,"")< IF(_uom="lbs", 175, 80), 1.25, IF(_uom="lbs",5,2.5))))), "")} | DU13: =IFERROR(__xludf.DUMMYFUNCTION("IF(DQ13=MAX(FILTER(DQ$10:DQ$199,LOOKUP(ROW(DK$10:DK$199),FILTER(ROW(DK$10:DK$199),DK$10:DK$199<>DK$9:DK$198))=LOOKUP(ROW(DK13),FILTER(ROW(DK$10:DK$199),DK$10:DK$199<>DK$9:DK$198)))),DR13,)"),"") | IW13: =IF(ISBLANK(#REF!),"",#REF!) -> #REF! | IY13: #REF!
